Workbook
Name Unchangable: 'Working Filter Page'!$B$4:$E$4
Name Unchangable: 'Easy Filter Page'!$B$4:$E$4
Name Unchangable: 'Dungeon Loot'!$A$1:$I$1

Sheet Easy Filter Page
C1: Loot Table Calculator | D1: Filter Value | E1: Filter Rarity | G1: Filter Category
A2: =IF(E2="Mundane", 1, IF(E2="Common", 2, IF(E2="Uncommon", 3, IF(E2="Rare", 4, IF(E2="Very Rare", 5, IF(E2="Legendary", 6, 0)))))) -> 1 | C2: Lowest: | D2: 100 | E2: Mundane | G2: Wondrous Item
A3: =IF(E3="Mundane", 1, IF(E3="Common", 2, IF(E3="Uncommon", 3, IF(E3="Rare", 4, IF(E3="Very Rare", 5, IF(E3="Legendary", 6, 0)))))) -> 3 | C3: Highest: | D3: 10000 | E3: Uncommon | G3: Weapon
A4: D100 Roll | B4: Name | C4: Description | D4: Est. Value | E4: Rarity | F4: Weight | G4: Category | H4: Properties | I4: Requirements | J4: Author | K4: Rarity Number
A5: 42644 | B5: =IFERROR(__xludf.DUMMYFUNCTION("FILTER('Dungeon Loot'!A2:K1004, ('Dungeon Loot'!C2:C1004 > D2), ('Dungeon Loot'!C2:C1004 < D3), ('Dungeon Loot'!J2:J1004 >= A2), ('Dungeon Loot'!J2:J1004 <= A3), ('Dungeon Loot'!F2:F1004=G2) + ('Dungeon Loot'!F2:F1004=G3))"),"Hidden Blade Bracer") -> Hidden Blade Bracer | C5: =IFERROR(__xludf.DUMMYFUNCTION("""COMPUTED_VALUE"""),"Concealed punching dagger-bracer") -> Concealed punching dagger-bracer | D5: =IFERROR(__xludf.DUMMYFUNCTION("""COMPUTED_VALUE"""),200.0) -> 200 | E5: =IFERROR(__xludf.DUMMYFUNCTION("""COMPUTED_VALUE"""),"Common") -> Common | F5: =IFERROR(__xludf.DUMMYFUNCTION("""COMPUTED_VALUE"""),2.0) -> 2 | G5: =IFERROR(__xludf.DUMMYFUNCTION("""COMPUTED_VALUE"""),"Weapon") -> Weapon | H5: =IFERROR(__xludf.DUMMYFUNCTION("""COMPUTED_VALUE"""),"1d4 Piercing - Finesse, Light - Range: 20/60 When you attack and hit a creature that is surprised with this dagger, it must make a Constitution saving throw DC 18. On a failed save, the target takes an extra 2d4 damage from your attack.") -> 1d4 Piercing - Finesse, Light - Range: 20/60 When you attack and hit a creature that is surprised with this dagger, it must make a Constitution saving throw DC 18. On a failed save, the target takes an extra 2d4 damage from your attack. | K5: =IFERROR(__xludf.DUMMYFUNCTION("""COMPUTED_VALUE"""),2.0) -> 2
A6: 11-20 | B6: =IFERROR(__xludf.DUMMYFUNCTION("""COMPUTED_VALUE"""),"Neverfull Waterskin") -> Neverfull Waterskin | C6: =IFERROR(__xludf.DUMMYFUNCTION("""COMPUTED_VALUE"""),"Neverfull Waterskin (It's always half empty.)") -> Neverfull Waterskin (It's always half empty.) | D6: =IFERROR(__xludf.DUMMYFUNCTION("""COMPUTED_VALUE"""),200.0) -> 200 | E6: =IFERROR(__xludf.DUMMYFUNCTION("""COMPUTED_VALUE"""),"Uncommon") -> Uncommon | F6: =IFERROR(__xludf.DUMMYFUNCTION("""COMPUTED_VALUE"""),1.0) -> 1 | G6: =IFERROR(__xludf.DUMMYFUNCTION("""COMPUTED_VALUE"""),"Wondrous Item") -> Wondrous Item | K6: =IFERROR(__xludf.DUMMYFUNCTION("""COMPUTED_VALUE"""),3.0) -> 3
A7: 21 - 30 | B7: =IFERROR(__xludf.DUMMYFUNCTION("""COMPUTED_VALUE"""),"Alchemy Jug") -> Alchemy Jug | C7: =IFERROR(__xludf.DUMMYFUNCTION("""COMPUTED_VALUE"""),"This ceramic jug appears to be able to hold a gallon of liquid and weighs 12 pounds whether full or empty. Sloshing sounds can be heard from within the jug when it is shaken, even if the jug is empty. You can use an action and name one liquid from the tab"&"le below to cause the jug to produce the chosen liquid. Afterward, you can uncork the jug as an action and pour that liquid out, up to 2 gallons per minute. The maximum amount of liquid the jug can produce depends on the liquid you named. Once the jug sta"&"rts producing a liquid, it can't produce a different one, or more of one that has reached its maximum, until the next dawn. ") -> This ceramic jug appears to be able to hold a gallon of liquid and weighs 12 pounds whether full or empty. Sloshing sounds can be heard from within the jug when it is shaken, even if the jug is empty. You can use an action and name one liquid from the table below to cause the jug to produce the chosen liquid. Afterward, you can uncork the jug as an action and pour that liquid out, up to 2 gallons per minute. The maximum amount of liquid the jug can produce depends on the liquid you named. Once the jug starts producing a liquid, it can't produce a different one, or more of one that has reached its maximum, until the next dawn. | D7: =IFERROR(__xludf.DUMMYFUNCTION("""COMPUTED_VALUE"""),6000.0) -> 6000 | E7: =IFERROR(__xludf.DUMMYFUNCTION("""COMPUTED_VALUE"""),"Uncommon") -> Uncommon | F7: =IFERROR(__xludf.DUMMYFUNCTION("""COMPUTED_VALUE"""),1.0) -> 1 | G7: =IFERROR(__xludf.DUMMYFUNCTION("""COMPUTED_VALUE"""),"Wondrous Item") -> Wondrous Item | J7: =IFERROR(__xludf.DUMMYFUNCTION("""COMPUTED_VALUE"""),"DMG") -> DMG | K7: =IFERROR(__xludf.DUMMYFUNCTION("""COMPUTED_VALUE"""),3.0) -> 3
A8: 31 - 40 | B8: =IFERROR(__xludf.DUMMYFUNCTION("""COMPUTED_VALUE"""),"Bag of Holding") -> Bag of Holding | C8: =IFERROR(__xludf.DUMMYFUNCTION("""COMPUTED_VALUE"""),"This bag has an interior space considerably larger than its outside dimensions, roughly 2 feet in diameter at the mouth and 4 feet deep. The bag can hold up to 500 pounds, not exceeding a volume of 64 cubic feet. The bag weighs 15 pounds, regardless of it"&"s contents. Retrieving an item from the bag requires an action. If the bag is overloaded, pierced, or torn, it ruptures and is destroyed, and its contents are scattered in the Astral Plane. If the bag is turned inside out, its contents spill forth, unharm"&"ed, but the bag must be put right before it can be used again. Breathing creatures inside the bag can survive up to a number of minutes equal to 10 divided by the number of creatures (minimum 1 minute), after which time they begin to suffocate. Placing a "&"bag of holding inside an extradimensional space created by a Heward's handy haversack, portable hole, or similar item instantly destroys both items and opens a gate to the Astral Plane. The gate originates where the one item was placed inside the other. A"&"ny creature within 10 feet of the gate is sucked through it to a random location on the Astral Plane. The gate then closes. The gate is one-way only and can't be reopened. ") -> This bag has an interior space considerably larger than its outside dimensions, roughly 2 feet in diameter at the mouth and 4 feet deep. The bag can hold up to 500 pounds, not exceeding a volume of 64 cubic feet. The bag weighs 15 pounds, regardless of its contents. Retrieving an item from the bag requires an action. If the bag is overloaded, pierced, or torn, it ruptures and is destroyed, and its contents are scattered in the Astral Plane. If the bag is turned inside out, its contents spill forth, unharmed, but the bag must be put right before it can be used again. Breathing creatures inside the bag can survive up to a number of minutes equal to 10 divided by the number of creatures (minimum 1 minute), after which time they begin to suffocate. Placing a bag of holding inside an extradimensional space created by a Heward's handy haversack, portable hole, or similar item instantly destroys both items and opens a gate to the Astral Plane. The gate originates where the one item was placed inside the other. Any creature within 10 feet of the gate is sucked through it to a random location on the Astral Plane. The gate then closes. The gate is one-way only and can't be reopened. | D8: =IFERROR(__xludf.DUMMYFUNCTION("""COMPUTED_VALUE"""),4000.0) -> 4000 | E8: =IFERROR(__xludf.DUMMYFUNCTION("""COMPUTED_VALUE"""),"Uncommon") -> Uncommon | F8: =IFERROR(__xludf.DUMMYFUNCTION("""COMPUTED_VALUE"""),15.0) -> 15 | G8: =IFERROR(__xludf.DUMMYFUNCTION("""COMPUTED_VALUE"""),"Wondrous Item") -> Wondrous Item | J8: =IFERROR(__xludf.DUMMYFUNCTION("""COMPUTED_VALUE"""),"DMG") -> DMG | K8: =IFERROR(__xludf.DUMMYFUNCTION("""COMPUTED_VALUE"""),3.0) -> 3
A9: 41 - 50 | B9: =IFERROR(__xludf.DUMMYFUNCTION("""COMPUTED_VALUE"""),"Bag of Tricks, Grey") -> Bag of Tricks, Grey | C9: =IFERROR(__xludf.DUMMYFUNCTION("""COMPUTED_VALUE"""),"This ordinary gray cloth bag appears to be empty. Reaching inside the bag, however, reveals the presence of a small, fuzzy object. You can use an action to pull the fuzzy object from the bag and throw it up to 20 feet. When the object lands, it transforms"&" into a creature you determine by rolling a d8 and consulting the table that corresponds to the bag’s color. The creature vanishes at the next dawn or when it is reduced to 0 hit points. The creature is friendly to you and your companions, and it acts on "&"your turn. You can use a bonus action to command how the creature moves and what action it takes on its next turn, or to give it general orders, such as to attack your enemies. In the absence of such orders, the creature acts in a fashion appropriate to i"&"ts nature. Once three fuzzy objects have been pulled from the bag, the bag cannot be used again until the next dawn. ") -> This ordinary gray cloth bag appears to be empty. Reaching inside the bag, however, reveals the presence of a small, fuzzy object. You can use an action to pull the fuzzy object from the bag and throw it up to 20 feet. When the object lands, it transforms into a creature you determine by rolling a d8 and consulting the table that corresponds to the bag’s color. The creature vanishes at the next dawn or when it is reduced to 0 hit points. The creature is friendly to you and your companions, and it acts on your turn. You can use a bonus action to command how the creature moves and what action it takes on its next turn, or to give it general orders, such as to attack your enemies. In the absence of such orders, the creature acts in a fashion appropriate to its nature. Once three fuzzy objects have been pulled from the bag, the bag cannot be used again until the next dawn. | D9: =IFERROR(__xludf.DUMMYFUNCTION("""COMPUTED_VALUE"""),900.0) -> 900 | E9: =IFERROR(__xludf.DUMMYFUNCTION("""COMPUTED_VALUE"""),"Uncommon") -> Uncommon | F9: =IFERROR(__xludf.DUMMYFUNCTION("""COMPUTED_VALUE"""),0.5) -> 0.5 | G9: =IFERROR(__xludf.DUMMYFUNCTION("""COMPUTED_VALUE"""),"Wondrous Item") -> Wondrous Item | J9: =IFERROR(__xludf.DUMMYFUNCTION("""COMPUTED_VALUE"""),"DMG") -> DMG | K9: =IFERROR(__xludf.DUMMYFUNCTION("""COMPUTED_VALUE"""),3.0) -> 3
A10: 51 - 55 | B10: =IFERROR(__xludf.DUMMYFUNCTION("""COMPUTED_VALUE"""),"Bat Sack") -> Bat Sack | C10: =IFERROR(__xludf.DUMMYFUNCTION("""COMPUTED_VALUE"""),"Witch’s Mad Sack of Bats – releases swarm of bats") -> Witch’s Mad Sack of Bats – releases swarm of bats | D10: =IFERROR(__xludf.DUMMYFUNCTION("""COMPUTED_VALUE"""),300.0) -> 300 | E10: =IFERROR(__xludf.DUMMYFUNCTION("""COMPUTED_VALUE"""),"Uncommon") -> Uncommon | F10: =IFERROR(__xludf.DUMMYFUNCTION("""COMPUTED_VALUE"""),1.0) -> 1 | G10: =IFERROR(__xludf.DUMMYFUNCTION("""COMPUTED_VALUE"""),"Wondrous Item") -> Wondrous Item | J10: =IFERROR(__xludf.DUMMYFUNCTION("""COMPUTED_VALUE"""),"PlatypusPal") -> PlatypusPal | K10: =IFERROR(__xludf.DUMMYFUNCTION("""COMPUTED_VALUE"""),3.0) -> 3
A11: 56 - 60 | B11: =IFERROR(__xludf.DUMMYFUNCTION("""COMPUTED_VALUE"""),"Bear Claw Boots") -> Bear Claw Boots | C11: =IFERROR(__xludf.DUMMYFUNCTION("""COMPUTED_VALUE"""),"A pair of dark leather boots upon which a curious gnomish mechanism has been fastened around. There is a small lever on the side of the ankle that, when toggled, extends on each boot a set of sharp mountaineering claws. The boots are sized for medium huma"&"noid but the mechanism itself would be easy enough for a blacksmith to scale up or down.") -> A pair of dark leather boots upon which a curious gnomish mechanism has been fastened around. There is a small lever on the side of the ankle that, when toggled, extends on each boot a set of sharp mountaineering claws. The boots are sized for medium humanoid but the mechanism itself would be easy enough for a blacksmith to scale up or down. | D11: =IFERROR(__xludf.DUMMYFUNCTION("""COMPUTED_VALUE"""),300.0) -> 300 | E11: =IFERROR(__xludf.DUMMYFUNCTION("""COMPUTED_VALUE"""),"Uncommon") -> Uncommon | F11: =IFERROR(__xludf.DUMMYFUNCTION("""COMPUTED_VALUE"""),4.0) -> 4 | G11: =IFERROR(__xludf.DUMMYFUNCTION("""COMPUTED_VALUE"""),"Wondrous Item") -> Wondrous Item | H11: =IFERROR(__xludf.DUMMYFUNCTION("""COMPUTED_VALUE"""),"The mountaineering claws provide a +2 circumstance bonus to climb checks. This bonus can be used in addition to a Climber's Kit.") -> The mountaineering claws provide a +2 circumstance bonus to climb checks. This bonus can be used in addition to a Climber's Kit. | J11: =IFERROR(__xludf.DUMMYFUNCTION("""COMPUTED_VALUE"""),"Uberbeard") -> Uberbeard | K11: =IFERROR(__xludf.DUMMYFUNCTION("""COMPUTED_VALUE"""),3.0) -> 3
A12: 61 - 65 | B12: =IFERROR(__xludf.DUMMYFUNCTION("""COMPUTED_VALUE"""),"Boots of Elvenkind") -> Boots of Elvenkind | C12: =IFERROR(__xludf.DUMMYFUNCTION("""COMPUTED_VALUE"""),"While you wear these boots, your steps make no sound, regardless of the surface you are moving across. You also have advantage on Dexterity (Stealth) checks that rely on moving silently. ") -> While you wear these boots, your steps make no sound, regardless of the surface you are moving across. You also have advantage on Dexterity (Stealth) checks that rely on moving silently. | D12: =IFERROR(__xludf.DUMMYFUNCTION("""COMPUTED_VALUE"""),2500.0) -> 2500 | E12: =IFERROR(__xludf.DUMMYFUNCTION("""COMPUTED_VALUE"""),"Uncommon") -> Uncommon | F12: =IFERROR(__xludf.DUMMYFUNCTION("""COMPUTED_VALUE"""),1.0) -> 1 | G12: =IFERROR(__xludf.DUMMYFUNCTION("""COMPUTED_VALUE"""),"Wondrous Item") -> Wondrous Item | J12: =IFERROR(__xludf.DUMMYFUNCTION("""COMPUTED_VALUE"""),"DMG") -> DMG | K12: =IFERROR(__xludf.DUMMYFUNCTION("""COMPUTED_VALUE"""),3.0) -> 3
A13: 66 - 70 | B13: =IFERROR(__xludf.DUMMYFUNCTION("""COMPUTED_VALUE"""),"Boots of Striding and Springing") -> Boots of Striding and Springing | C13: =IFERROR(__xludf.DUMMYFUNCTION("""COMPUTED_VALUE"""),"A pair of tan boots which are fastened around the foot with three adjustable belts. The inner sole of these boots feels springy to the touch and seems to mould itself around the user's foot for a fit so comfortable it's like walking on the clouds.") -> A pair of tan boots which are fastened around the foot with three adjustable belts. The inner sole of these boots feels springy to the touch and seems to mould itself around the user's foot for a fit so comfortable it's like walking on the clouds. | D13: =IFERROR(__xludf.DUMMYFUNCTION("""COMPUTED_VALUE"""),5000.0) -> 5000 | E13: =IFERROR(__xludf.DUMMYFUNCTION("""COMPUTED_VALUE"""),"Uncommon") -> Uncommon | F13: =IFERROR(__xludf.DUMMYFUNCTION("""COMPUTED_VALUE"""),1.0) -> 1 | G13: =IFERROR(__xludf.DUMMYFUNCTION("""COMPUTED_VALUE"""),"Wondrous Item") -> Wondrous Item | H13: =IFERROR(__xludf.DUMMYFUNCTION("""COMPUTED_VALUE"""),"While you wear these boots, your walking speed becomes 30 feet, unless your walking speed is higher, and your speed isn't reduced if you are encumbered or wearing heavy armor. In addition, you can jump three times the normal distance, though you can't jum"&"p farther than your remaining movement would allow.") -> While you wear these boots, your walking speed becomes 30 feet, unless your walking speed is higher, and your speed isn't reduced if you are encumbered or wearing heavy armor. In addition, you can jump three times the normal distance, though you can't jump farther than your remaining movement would allow. | I13: =IFERROR(__xludf.DUMMYFUNCTION("""COMPUTED_VALUE"""),"Requires Attunement") -> Requires Attunement | J13: =IFERROR(__xludf.DUMMYFUNCTION("""COMPUTED_VALUE"""),"DMG") -> DMG | K13: =IFERROR(__xludf.DUMMYFUNCTION("""COMPUTED_VALUE"""),3.0) -> 3
A14: 71 - 75 | B14: =IFERROR(__xludf.DUMMYFUNCTION("""COMPUTED_VALUE"""),"Boots of the Winterlands") -> Boots of the Winterlands | C14: =IFERROR(__xludf.DUMMYFUNCTION("""COMPUTED_VALUE"""),"A pair of hide boots lined with dense, warm white fur. The eyelet for each bootlace is patterned with small gemstones and the sole of the boot is spiked so as to benefit the user over icy and unstable terrain. These furred boots are snug and feel quite wa"&"rm. ") -> A pair of hide boots lined with dense, warm white fur. The eyelet for each bootlace is patterned with small gemstones and the sole of the boot is spiked so as to benefit the user over icy and unstable terrain. These furred boots are snug and feel quite warm. | D14: =IFERROR(__xludf.DUMMYFUNCTION("""COMPUTED_VALUE"""),2500.0) -> 2500 | E14: =IFERROR(__xludf.DUMMYFUNCTION("""COMPUTED_VALUE"""),"Uncommon") -> Uncommon | F14: =IFERROR(__xludf.DUMMYFUNCTION("""COMPUTED_VALUE"""),1.0) -> 1 | G14: =IFERROR(__xludf.DUMMYFUNCTION("""COMPUTED_VALUE"""),"Wondrous Item") -> Wondrous Item | H14: =IFERROR(__xludf.DUMMYFUNCTION("""COMPUTED_VALUE"""),"See DMG page 156.") -> See DMG page 156. | I14: =IFERROR(__xludf.DUMMYFUNCTION("""COMPUTED_VALUE"""),"Requires Attunement") -> Requires Attunement | J14: =IFERROR(__xludf.DUMMYFUNCTION("""COMPUTED_VALUE"""),"DMG") -> DMG | K14: =IFERROR(__xludf.DUMMYFUNCTION("""COMPUTED_VALUE"""),3.0) -> 3
A15: 76 - 80 | B15: =IFERROR(__xludf.DUMMYFUNCTION("""COMPUTED_VALUE"""),"Bracers of Archery") -> Bracers of Archery | C15: =IFERROR(__xludf.DUMMYFUNCTION("""COMPUTED_VALUE"""),"While wearing these bracers, you have proficiency with the longbow and shortbow, and you gain a +2 bonus to damage rolls on ranged attacks made with such weapons.") -> While wearing these bracers, you have proficiency with the longbow and shortbow, and you gain a +2 bonus to damage rolls on ranged attacks made with such weapons. | D15: =IFERROR(__xludf.DUMMYFUNCTION("""COMPUTED_VALUE"""),1500.0) -> 1500 | E15: =IFERROR(__xludf.DUMMYFUNCTION("""COMPUTED_VALUE"""),"Uncommon") -> Uncommon | F15: =IFERROR(__xludf.DUMMYFUNCTION("""COMPUTED_VALUE"""),1.0) -> 1 | G15: =IFERROR(__xludf.DUMMYFUNCTION("""COMPUTED_VALUE"""),"Wondrous Item") -> Wondrous Item | I15: =IFERROR(__xludf.DUMMYFUNCTION("""COMPUTED_VALUE"""),"Requires Attunement") -> Requires Attunement | J15: =IFERROR(__xludf.DUMMYFUNCTION("""COMPUTED_VALUE"""),"DMG") -> DMG | K15: =IFERROR(__xludf.DUMMYFUNCTION("""COMPUTED_VALUE"""),3.0) -> 3
A16: 81 - 85 | B16: =IFERROR(__xludf.DUMMYFUNCTION("""COMPUTED_VALUE"""),"Bracers of Binding") -> Bracers of Binding | C16: =IFERROR(__xludf.DUMMYFUNCTION("""COMPUTED_VALUE"""),"The bracers appear to be Bracers of Specialization, but when donned, bind the wearer wrists together, making it quite difficult to wield a weapon or cast a spell. These bracers are sometimes offered as rewards for services rendered by the Drow. The recipi"&"ent, believing them to be very powerful, will often don them before examinating them. At this point, the drow find it amusing to conjure a hook horror. ") -> The bracers appear to be Bracers of Specialization, but when donned, bind the wearer wrists together, making it quite difficult to wield a weapon or cast a spell. These bracers are sometimes offered as rewards for services rendered by the Drow. The recipient, believing them to be very powerful, will often don them before examinating them. At this point, the drow find it amusing to conjure a hook horror. | D16: =IFERROR(__xludf.DUMMYFUNCTION("""COMPUTED_VALUE"""),300.0) -> 300 | E16: =IFERROR(__xludf.DUMMYFUNCTION("""COMPUTED_VALUE"""),"Uncommon") -> Uncommon | F16: =IFERROR(__xludf.DUMMYFUNCTION("""COMPUTED_VALUE"""),"n/a") -> n/a | G16: =IFERROR(__xludf.DUMMYFUNCTION("""COMPUTED_VALUE"""),"Wondrous Item") -> Wondrous Item | H16: =IFERROR(__xludf.DUMMYFUNCTION("""COMPUTED_VALUE"""),"lower damage by 5 points, increase spell failure to 75% and give the wearer a +5 penalty to THACO. Since they are cursed, they can't be unequiped without a Remove Curse spell or the services of a priest") -> lower damage by 5 points, increase spell failure to 75% and give the wearer a +5 penalty to THACO. Since they are cursed, they can't be unequiped without a Remove Curse spell or the services of a priest | J16: =IFERROR(__xludf.DUMMYFUNCTION("""COMPUTED_VALUE"""),"BGII") -> BGII | K16: =IFERROR(__xludf.DUMMYFUNCTION("""COMPUTED_VALUE"""),3.0) -> 3
A17: 86 - 90 | B17: =IFERROR(__xludf.DUMMYFUNCTION("""COMPUTED_VALUE"""),"Brooch of Shielding") -> Brooch of Shielding | C17: =IFERROR(__xludf.DUMMYFUNCTION("""COMPUTED_VALUE"""),"While wearing this brooch, you have resistance to force damage, and you have immunity to damage from the magic missile spell. ") -> While wearing this brooch, you have resistance to force damage, and you have immunity to damage from the magic missile spell. | D17: =IFERROR(__xludf.DUMMYFUNCTION("""COMPUTED_VALUE"""),7500.0) -> 7500 | E17: =IFERROR(__xludf.DUMMYFUNCTION("""COMPUTED_VALUE"""),"Uncommon") -> Uncommon | F17: =IFERROR(__xludf.DUMMYFUNCTION("""COMPUTED_VALUE"""),"n/a") -> n/a | G17: =IFERROR(__xludf.DUMMYFUNCTION("""COMPUTED_VALUE"""),"Wondrous Item") -> Wondrous Item | I17: =IFERROR(__xludf.DUMMYFUNCTION("""COMPUTED_VALUE"""),"Requires Attunement") -> Requires Attunement | J17: =IFERROR(__xludf.DUMMYFUNCTION("""COMPUTED_VALUE"""),"DMG") -> DMG | K17: =IFERROR(__xludf.DUMMYFUNCTION("""COMPUTED_VALUE"""),3.0) -> 3
A18: 91 | B18: =IFERROR(__xludf.DUMMYFUNCTION("""COMPUTED_VALUE"""),"Broom of Flying") -> Broom of Flying | C18: =IFERROR(__xludf.DUMMYFUNCTION("""COMPUTED_VALUE"""),"This wooden broom functions like a mundane broom until you stand astride it and speak its command word. It then hovers beneath you and can be ridden in the air. The broom stops hovering when you land. You can send the broom to travel alone to a destinatio"&"n within 1 mile of you if you speak the command word, name the location, and are familiar with that place. The broom comes back to you when you speak another command word, provided that the broom is still within 1 mile of you. ") -> This wooden broom functions like a mundane broom until you stand astride it and speak its command word. It then hovers beneath you and can be ridden in the air. The broom stops hovering when you land. You can send the broom to travel alone to a destination within 1 mile of you if you speak the command word, name the location, and are familiar with that place. The broom comes back to you when you speak another command word, provided that the broom is still within 1 mile of you. | D18: =IFERROR(__xludf.DUMMYFUNCTION("""COMPUTED_VALUE"""),8000.0) -> 8000 | E18: =IFERROR(__xludf.DUMMYFUNCTION("""COMPUTED_VALUE"""),"Uncommon") -> Uncommon | F18: =IFERROR(__xludf.DUMMYFUNCTION("""COMPUTED_VALUE"""),3.0) -> 3 | G18: =IFERROR(__xludf.DUMMYFUNCTION("""COMPUTED_VALUE"""),"Wondrous Item") -> Wondrous Item | H18: =IFERROR(__xludf.DUMMYFUNCTION("""COMPUTED_VALUE"""),"It has a flying speed of 50 feet. It can carry up to 400 pounds, but its flying speed becomes 30 feet while carrying over 200 pounds. ") -> It has a flying speed of 50 feet. It can carry up to 400 pounds, but its flying speed becomes 30 feet while carrying over 200 pounds. | J18: =IFERROR(__xludf.DUMMYFUNCTION("""COMPUTED_VALUE"""),"DMG") -> DMG | K18: =IFERROR(__xludf.DUMMYFUNCTION("""COMPUTED_VALUE"""),3.0) -> 3
A19: 92 | B19: =IFERROR(__xludf.DUMMYFUNCTION("""COMPUTED_VALUE"""),"Cap of Water Breathing") -> Cap of Water Breathing | C19: =IFERROR(__xludf.DUMMYFUNCTION("""COMPUTED_VALUE"""),"The word “STYX” is sewn into the inner headband of this cap.") -> The word “STYX” is sewn into the inner headband of this cap. | D19: =IFERROR(__xludf.DUMMYFUNCTION("""COMPUTED_VALUE"""),1000.0) -> 1000 | E19: =IFERROR(__xludf.DUMMYFUNCTION("""COMPUTED_VALUE"""),"Uncommon") -> Uncommon | F19: =IFERROR(__xludf.DUMMYFUNCTION("""COMPUTED_VALUE"""),1.0) -> 1 | G19: =IFERROR(__xludf.DUMMYFUNCTION("""COMPUTED_VALUE"""),"Wondrous Item") -> Wondrous Item | H19: =IFERROR(__xludf.DUMMYFUNCTION("""COMPUTED_VALUE"""),"While wearing this cap underwater you can speak its command word as an action to create a bubble of air arround your head. It allows you to breathing normally underwater. This bubble stays with you until you speak the command word again, the cap is remove"&"d or you are no longer underwater.") -> While wearing this cap underwater you can speak its command word as an action to create a bubble of air arround your head. It allows you to breathing normally underwater. This bubble stays with you until you speak the command word again, the cap is removed or you are no longer underwater. | J19: =IFERROR(__xludf.DUMMYFUNCTION("""COMPUTED_VALUE"""),"DMG") -> DMG | K19: =IFERROR(__xludf.DUMMYFUNCTION("""COMPUTED_VALUE"""),3.0) -> 3
A20: 93 | B20: =IFERROR(__xludf.DUMMYFUNCTION("""COMPUTED_VALUE"""),"Edible Greatsword") -> Edible Greatsword | C20: =IFERROR(__xludf.DUMMYFUNCTION("""COMPUTED_VALUE"""),"Works like a normal greatsword. Great tasting and low in calories! Regenerates 6 inches per day.") -> Works like a normal greatsword. Great tasting and low in calories! Regenerates 6 inches per day. | D20: =IFERROR(__xludf.DUMMYFUNCTION("""COMPUTED_VALUE"""),400.0) -> 400 | E20: =IFERROR(__xludf.DUMMYFUNCTION("""COMPUTED_VALUE"""),"Uncommon") -> Uncommon | F20: =IFERROR(__xludf.DUMMYFUNCTION("""COMPUTED_VALUE"""),6.0) -> 6 | G20: =IFERROR(__xludf.DUMMYFUNCTION("""COMPUTED_VALUE"""),"Weapon") -> Weapon | H20: =IFERROR(__xludf.DUMMYFUNCTION("""COMPUTED_VALUE"""),"2d6 Slashing - Heavy - Two-Handed") -> 2d6 Slashing - Heavy - Two-Handed | I20: =IFERROR(__xludf.DUMMYFUNCTION("""COMPUTED_VALUE"""),"Martial Weapon Expertise") -> Martial Weapon Expertise | J20: =IFERROR(__xludf.DUMMYFUNCTION("""COMPUTED_VALUE"""),"Uberbeard") -> Uberbeard | K20: =IFERROR(__xludf.DUMMYFUNCTION("""COMPUTED_VALUE"""),3.0) -> 3
A21: 94 | B21: =IFERROR(__xludf.DUMMYFUNCTION("""COMPUTED_VALUE"""),"Sentient Dagger of Sneaking") -> Sentient Dagger of Sneaking | C21: =IFERROR(__xludf.DUMMYFUNCTION("""COMPUTED_VALUE"""),"This sentient dagger attempts to help anytime it's owner tries to sneak by whistling inconspicuously. For some reason it seems to have been discarded.") -> This sentient dagger attempts to help anytime it's owner tries to sneak by whistling inconspicuously. For some reason it seems to have been discarded. | D21: =IFERROR(__xludf.DUMMYFUNCTION("""COMPUTED_VALUE"""),300.0) -> 300 | E21: =IFERROR(__xludf.DUMMYFUNCTION("""COMPUTED_VALUE"""),"Uncommon") -> Uncommon | F21: =IFERROR(__xludf.DUMMYFUNCTION("""COMPUTED_VALUE"""),1.0) -> 1 | G21: =IFERROR(__xludf.DUMMYFUNCTION("""COMPUTED_VALUE"""),"Weapon") -> Weapon | H21: =IFERROR(__xludf.DUMMYFUNCTION("""COMPUTED_VALUE"""),"1d4 Piercing - Finesse, Light - Range: 20/60") -> 1d4 Piercing - Finesse, Light - Range: 20/60 | J21: =IFERROR(__xludf.DUMMYFUNCTION("""COMPUTED_VALUE"""),"Uberbeard") -> Uberbeard | K21: =IFERROR(__xludf.DUMMYFUNCTION("""COMPUTED_VALUE"""),3.0) -> 3
A22: 95 | B22: =IFERROR(__xludf.DUMMYFUNCTION("""COMPUTED_VALUE"""),"Boomerang of Retrieval") -> Boomerang of Retrieval | C22: =IFERROR(__xludf.DUMMYFUNCTION("""COMPUTED_VALUE"""),"This otherwise normal looking boomerang has a sense of arcana deep within it's dark oak core. Researching it's history will reveal that this is, in fact, one of many created by a local wizard who was frustrated at being unable to throw a normal boomerang "&"in such a way that it returned naturally.") -> This otherwise normal looking boomerang has a sense of arcana deep within it's dark oak core. Researching it's history will reveal that this is, in fact, one of many created by a local wizard who was frustrated at being unable to throw a normal boomerang in such a way that it returned naturally. | D22: =IFERROR(__xludf.DUMMYFUNCTION("""COMPUTED_VALUE"""),180.0) -> 180 | E22: =IFERROR(__xludf.DUMMYFUNCTION("""COMPUTED_VALUE"""),"Uncommon") -> Uncommon | F22: =IFERROR(__xludf.DUMMYFUNCTION("""COMPUTED_VALUE"""),2.0) -> 2 | G22: =IFERROR(__xludf.DUMMYFUNCTION("""COMPUTED_VALUE"""),"Weapon") -> Weapon | H22: =IFERROR(__xludf.DUMMYFUNCTION("""COMPUTED_VALUE"""),"1d6 Bludgeoning (+1 force damage) - Thrown (Range: 30/90) Special: Does not require direct line of sight, due to a curved trajectory. Unlike a normal boomerang, the boomerang of retrieval will always return to you after you make a ranged attack with it, "&"even if you hit.") -> 1d6 Bludgeoning (+1 force damage) - Thrown (Range: 30/90) Special: Does not require direct line of sight, due to a curved trajectory. Unlike a normal boomerang, the boomerang of retrieval will always return to you after you make a ranged attack with it, even if you hit. | J22: =IFERROR(__xludf.DUMMYFUNCTION("""COMPUTED_VALUE"""),"D&D Wiki") -> D&D Wiki | K22: =IFERROR(__xludf.DUMMYFUNCTION("""COMPUTED_VALUE"""),3.0) -> 3
A23: 96 | B23: =IFERROR(__xludf.DUMMYFUNCTION("""COMPUTED_VALUE"""),"Gnome Timepiece") -> Gnome Timepiece | C23: =IFERROR(__xludf.DUMMYFUNCTION("""COMPUTED_VALUE"""),"A magical time-keeping device produced by a Gnomish artisan. Opening this circular locket allows you to check the current time based on where a delicate hand is pointing. On one half of the circular face is an ornate night's sky with a crescent moon indic"&"ating midnight. On the other half is a blue sky, with a bright sun indicating mid-day. It's unclear how the magic has been infused with the device, as no arcane presence is detectable, but pulling the silver panel off the back of the locket simply exposes"&" a number of delicate, ticking gears. Gnome magic is compicated.") -> A magical time-keeping device produced by a Gnomish artisan. Opening this circular locket allows you to check the current time based on where a delicate hand is pointing. On one half of the circular face is an ornate night's sky with a crescent moon indicating midnight. On the other half is a blue sky, with a bright sun indicating mid-day. It's unclear how the magic has been infused with the device, as no arcane presence is detectable, but pulling the silver panel off the back of the locket simply exposes a number of delicate, ticking gears. Gnome magic is compicated. | D23: =IFERROR(__xludf.DUMMYFUNCTION("""COMPUTED_VALUE"""),150.0) -> 150 | E23: =IFERROR(__xludf.DUMMYFUNCTION("""COMPUTED_VALUE"""),"Uncommon") -> Uncommon | F23: =IFERROR(__xludf.DUMMYFUNCTION("""COMPUTED_VALUE"""),"n/a") -> n/a | G23: =IFERROR(__xludf.DUMMYFUNCTION("""COMPUTED_VALUE"""),"Wondrous Item") -> Wondrous Item | J23: =IFERROR(__xludf.DUMMYFUNCTION("""COMPUTED_VALUE"""),"Uberbeard") -> Uberbeard | K23: =IFERROR(__xludf.DUMMYFUNCTION("""COMPUTED_VALUE"""),3.0) -> 3
A24: 97 | B24: =IFERROR(__xludf.DUMMYFUNCTION("""COMPUTED_VALUE"""),"The Living Lantern") -> The Living Lantern | C24: =IFERROR(__xludf.DUMMYFUNCTION("""COMPUTED_VALUE"""),"An an ordinary candle lamp with a glass surround and handle.") -> An an ordinary candle lamp with a glass surround and handle. | D24: =IFERROR(__xludf.DUMMYFUNCTION("""COMPUTED_VALUE"""),1000.0) -> 1000 | E24: =IFERROR(__xludf.DUMMYFUNCTION("""COMPUTED_VALUE"""),"Uncommon") -> Uncommon | F24: =IFERROR(__xludf.DUMMYFUNCTION("""COMPUTED_VALUE"""),2.0) -> 2 | G24: =IFERROR(__xludf.DUMMYFUNCTION("""COMPUTED_VALUE"""),"Wondrous Item") -> Wondrous Item | H24: =IFERROR(__xludf.DUMMYFUNCTION("""COMPUTED_VALUE"""),"When used the candle on this lantern does not burn down and the luminosity of the lantern is far beyond what a simple hooded lantern should be capable of. Once lit, the lantern slowly grows in light level until it is dangerous to look at directly. It also"&" slowly comes to consciousness, as if being roused from a deep sleep. After an hour, the lantern is fully sapient and can parlay with the party. It has a deep desire to burn everything flammable (and can do so), but may be tempered with the promise of bei"&"ng kept alight for longer. For the first 30 minutes it provides light at a range of 60/90 ft. This grows by 30 ft for every 30 minutes after. If left on for more than 3 hours the lantern becomes so hot it will set fire to anything flammable in a 5 foot r"&"ange. It can be extinguished with a command word written on the base of the lantern.") -> When used the candle on this lantern does not burn down and the luminosity of the lantern is far beyond what a simple hooded lantern should be capable of. Once lit, the lantern slowly grows in light level until it is dangerous to look at directly. It also slowly comes to consciousness, as if being roused from a deep sleep. After an hour, the lantern is fully sapient and can parlay with the party. It has a deep desire to burn everything flammable (and can do so), but may be tempered with the promise of being kept alight for longer. For the first 30 minutes it provides light at a range of 60/90 ft. This grows by 30 ft for every 30 minutes after. If left on for more than 3 hours the lantern becomes so hot it will set fire to anything flammable in a 5 foot range. It can be extinguished with a command word written on the base of the lantern. | J24: =IFERROR(__xludf.DUMMYFUNCTION("""COMPUTED_VALUE"""),"Uberbeard") -> Uberbeard | K24: =IFERROR(__xludf.DUMMYFUNCTION("""COMPUTED_VALUE"""),3.0) -> 3
A25: 98 | B25: =IFERROR(__xludf.DUMMYFUNCTION("""COMPUTED_VALUE"""),"Waterskin of Inexplicable Amelioration") -> Waterskin of Inexplicable Amelioration | C25: =IFERROR(__xludf.DUMMYFUNCTION("""COMPUTED_VALUE"""),"A sheep's bladder waterskin. It is lined with a suedelike fabric which has been beautifully stiched with the image of a stag's head. ") -> A sheep's bladder waterskin. It is lined with a suedelike fabric which has been beautifully stiched with the image of a stag's head. | D25: =IFERROR(__xludf.DUMMYFUNCTION("""COMPUTED_VALUE"""),600.0) -> 600 | E25: =IFERROR(__xludf.DUMMYFUNCTION("""COMPUTED_VALUE"""),"Uncommon") -> Uncommon | G25: =IFERROR(__xludf.DUMMYFUNCTION("""COMPUTED_VALUE"""),"Wondrous Item") -> Wondrous Item | H25: =IFERROR(__xludf.DUMMYFUNCTION("""COMPUTED_VALUE"""),"When any liquid is poured into this waterskin it is instantly purified of disease, poison or other potentially harmful contaminents.") -> When any liquid is poured into this waterskin it is instantly purified of disease, poison or other potentially harmful contaminents. | K25: =IFERROR(__xludf.DUMMYFUNCTION("""COMPUTED_VALUE"""),3.0) -> 3
A26: 99 | B26: =IFERROR(__xludf.DUMMYFUNCTION("""COMPUTED_VALUE"""),"Greedy Bag of Holding") -> Greedy Bag of Holding | C26: =IFERROR(__xludf.DUMMYFUNCTION("""COMPUTED_VALUE"""),"This appears to be a common cloth sack about 2 feet by 4 feet in size. ") -> This appears to be a common cloth sack about 2 feet by 4 feet in size. | D26: =IFERROR(__xludf.DUMMYFUNCTION("""COMPUTED_VALUE"""),500.0) -> 500 | E26: =IFERROR(__xludf.DUMMYFUNCTION("""COMPUTED_VALUE"""),"Uncommon") -> Uncommon | F26: =IFERROR(__xludf.DUMMYFUNCTION("""COMPUTED_VALUE"""),15.0) -> 15 | G26: =IFERROR(__xludf.DUMMYFUNCTION("""COMPUTED_VALUE"""),"Wondrous Item") -> Wondrous Item | H26: =IFERROR(__xludf.DUMMYFUNCTION("""COMPUTED_VALUE"""),"This functions as a normal Bag of Holding, but for every item you wish to remove from the bag you must put in a silver piece. Any money placed into the bag dissapears almost immediately. It's unclear where the coins go when placed into the bag.") -> This functions as a normal Bag of Holding, but for every item you wish to remove from the bag you must put in a silver piece. Any money placed into the bag dissapears almost immediately. It's unclear where the coins go when placed into the bag. | J26: =IFERROR(__xludf.DUMMYFUNCTION("""COMPUTED_VALUE"""),"William Orfanakos") -> William Orfanakos | K26: =IFERROR(__xludf.DUMMYFUNCTION("""COMPUTED_VALUE"""),3.0) -> 3
A27: 100

Sheet Dungeon Loot
A1: Item | B1: Description | C1: Est. Value | D1: Rarity | E1: Weight | F1: Category | G1: Properties | H1: Requirements | I1: Author | J1: Rarity Number
A2: Oily Rags | B2: Three oily rags in an old wicker basket. | C2: 0.2 | D2: Mundane | E2: n/a | F2: Treasure | I2: Uberbeard | J2: =IF(D2="Mundane", 1, IF(D2="Common", 2, IF(D2="Uncommon", 3, IF(D2="Rare", 4, IF(D2="Very Rare", 5, IF(D2="Legendary", 6, 100)))))) -> 1
A3: Pickle | B3: On the floor, you find a single pickle wrapped in an oily paper bag. It has a strong distinct smell, but otherwise seems like a normal pickle. | C3: 0.05 | D3: Mundane | E3: 1 | F3: Treasure | I3: Unknown | J3: =IF(D3="Mundane", 1, IF(D3="Common", 2, IF(D3="Uncommon", 3, IF(D3="Rare", 4, IF(D3="Very Rare", 5, IF(D3="Legendary", 6, 100)))))) -> 1
A4: Ancient Sword | B4: A used, slightly rusted double-bladed sword. | C4: 2 | D4: Mundane | E4: 3 | F4: Weapon | G4: 1d4 Piercing - Finesse, Light | I4: PlatypusPal | J4: =IF(D4="Mundane", 1, IF(D4="Common", 2, IF(D4="Uncommon", 3, IF(D4="Rare", 4, IF(D4="Very Rare", 5, IF(D4="Legendary", 6, 100)))))) -> 1
A5: Andar Gem | B5: Andar is hard and durable, yielding translucent gems that flash green-red or brown-red when properly faceted. | C5: 15 | D5: Mundane | E5: n/a | F5: Treasure | I5: Baldur's Gate | J5: =IF(D5="Mundane", 1, IF(D5="Common", 2, IF(D5="Uncommon", 3, IF(D5="Rare", 4, IF(D5="Very Rare", 5, IF(D5="Legendary", 6, 100)))))) -> 1
A6: Banded Agate Gem | B6: A round translucent white gemstone with a ring of striped brown through its center. | C6: 10 | D6: Mundane | E6: n/a | F6: Treasure | I6: DMG | J6: =IF(D6="Mundane", 1, IF(D6="Common", 2, IF(D6="Uncommon", 3, IF(D6="Rare", 4, IF(D6="Very Rare", 5, IF(D6="Legendary", 6, 100)))))) -> 1
A7: Barrel o' Eels | B7: A large barrel of pickled eels. The barrel can be re-used, but it's unlikely the smell of pickled eel will ever truly be washed out. | C7: 5 | D7: Mundane | E7: 35 | F7: Treasure | I7: Uberbeard | J7: =IF(D7="Mundane", 1, IF(D7="Common", 2, IF(D7="Uncommon", 3, IF(D7="Rare", 4, IF(D7="Very Rare", 5, IF(D7="Legendary", 6, 100)))))) -> 1
A8: Barrel o' Nails | B8: A newly crafted barrel filled with iron nails. Might be difficult for the players to get this around if they don't have a cart. | C8: 5 | D8: Mundane | E8: 40 | F8: Treasure | I8: Uberbeard | J8: =IF(D8="Mundane", 1, IF(D8="Common", 2, IF(D8="Uncommon", 3, IF(D8="Rare", 4, IF(D8="Very Rare", 5, IF(D8="Legendary", 6, 100)))))) -> 1
A9: Beaver Pelts | B9: A string of eight beaver pelts. | C9: 1 | D9: Mundane | E9: 20 | F9: Treasure | I9: Uberbeard | J9: =IF(D9="Mundane", 1, IF(D9="Common", 2, IF(D9="Uncommon", 3, IF(D9="Rare", 4, IF(D9="Very Rare", 5, IF(D9="Legendary", 6, 100)))))) -> 1
A10: Belt | B10: An old leather belt. | C10: 0.15 | D10: Mundane | E10: 1 | F10: Treasure | I10: Uberbeard | J10: =IF(D10="Mundane", 1, IF(D10="Common", 2, IF(D10="Uncommon", 3, IF(D10="Rare", 4, IF(D10="Very Rare", 5, IF(D10="Legendary", 6, 100)))))) -> 1
A11: Black Velvet Mask | B11: An ornate black velvet mask sitched with silver thread. | C11: 25 | D11: Mundane | E11: n/a | F11: Treasure | I11: DMG | J11: =IF(D11="Mundane", 1, IF(D11="Common", 2, IF(D11="Uncommon", 3, IF(D11="Rare", 4, IF(D11="Very Rare", 5, IF(D11="Legendary", 6, 100)))))) -> 1
A12: Blank Scroll | B12: A blank scroll. It could have any spell in the world on it, eventually. The possibilities are endless. | C12: 0.5 | D12: Mundane | E12: n/a | F12: Treasure | I12: Uberbeard | J12: =IF(D12="Mundane", 1, IF(D12="Common", 2, IF(D12="Uncommon", 3, IF(D12="Rare", 4, IF(D12="Very Rare", 5, IF(D12="Legendary", 6, 100)))))) -> 1
A13: Blanket | B13: A thick woolen blanket. Something like this is perfect for wrapping up during those long cold nights spent staring at a cave wall. | C13: 0.35 | D13: Mundane | E13: 3 | F13: Adventuring Gear | I13: PHB | J13: =IF(D13="Mundane", 1, IF(D13="Common", 2, IF(D13="Uncommon", 3, IF(D13="Rare", 4, IF(D13="Very Rare", 5, IF(D13="Legendary", 6, 100)))))) -> 1
A14: Blood Stained Dress | B14: A blood-stained dress which, despite being found in ruins which have lain undisturbed for centuries, is still a vibrant, stunning blue. | C14: 2 | D14: Mundane | E14: 2 | F14: Treasure | I14: Uberbeard | J14: =IF(D14="Mundane", 1, IF(D14="Common", 2, IF(D14="Uncommon", 3, IF(D14="Rare", 4, IF(D14="Very Rare", 5, IF(D14="Legendary", 6, 100)))))) -> 1
A15: Blood-Soaked Book | B15: A blood-soaked book; a partially written history about a long-lost keep on the borderlands. The last written page is done in a different hand, and is scrawled with “The rules have changed!” in large, bold letters. Roughly a third of the book (of 100 pages) has been used. | C15: 5 | D15: Mundane | E15: 1 | F15: Book | H15: Language: Common | I15: Unknown | J15: =IF(D15="Mundane", 1, IF(D15="Common", 2, IF(D15="Uncommon", 3, IF(D15="Rare", 4, IF(D15="Very Rare", 5, IF(D15="Legendary", 6, 100)))))) -> 1
A16: Blue Quartz Gem | B16: A small quartz gemstone shaped in a bevelled square. It is transparent pale blue in color. | C16: 10 | D16: Mundane | E16: n/a | F16: Treasure | I16: DMG | J16: =IF(D16="Mundane", 1, IF(D16="Common", 2, IF(D16="Uncommon", 3, IF(D16="Rare", 4, IF(D16="Very Rare", 5, IF(D16="Legendary", 6, 100)))))) -> 1
A17: Blue Scarf | B17: A finely woven blue wool scarf. | C17: 1 | D17: Mundane | E17: n/a | F17: Treasure | I17: Uberbeard | J17: =IF(D17="Mundane", 1, IF(D17="Common", 2, IF(D17="Uncommon", 3, IF(D17="Rare", 4, IF(D17="Very Rare", 5, IF(D17="Legendary", 6, 100)))))) -> 1
A18: Bone Butter Churn | B18: A butter churn made of bone slats, bound with hoops of silver. A scrimshaw scene depicting a crowd of human villagers beating a Halfling with shovels and hoes wraps around it. | C18: 0.5 | D18: Mundane | E18: 1 | F18: Treasure | I18: Unknown | J18: =IF(D18="Mundane", 1, IF(D18="Common", 2, IF(D18="Uncommon", 3, IF(D18="Rare", 4, IF(D18="Very Rare", 5, IF(D18="Legendary", 6, 100)))))) -> 1
A19: Bone Dice | B19: A pair of engraved bone dice. | C19: 25 | D19: Mundane | E19: n/a | F19: Treasure | I19: DMG | J19: =IF(D19="Mundane", 1, IF(D19="Common", 2, IF(D19="Uncommon", 3, IF(D19="Rare", 4, IF(D19="Very Rare", 5, IF(D19="Legendary", 6, 100)))))) -> 1
A20: Bone Fragments | B20: Bits of bone from an unknown creature. | C20: 0 | D20: Mundane | E20: n/a | F20: Treasure | I20: Uberbeard | J20: =IF(D20="Mundane", 1, IF(D20="Common", 2, IF(D20="Uncommon", 3, IF(D20="Rare", 4, IF(D20="Very Rare", 5, IF(D20="Legendary", 6, 100)))))) -> 1
A21: Bone Needle | B21: A long needle carved out of bone. | C21: 0.25 | D21: Mundane | E21: n/a | F21: Treasure | I21: Uberbeard | J21: =IF(D21="Mundane", 1, IF(D21="Common", 2, IF(D21="Uncommon", 3, IF(D21="Rare", 4, IF(D21="Very Rare", 5, IF(D21="Legendary", 6, 100)))))) -> 1
A22: Broken Sword | B22: This is simply a regular sword that has been partially broken, in combat or however. Most people would just get rid of it, but maybe this sword has a nice hilt or sentimental value. | C22: 0.5 | D22: Mundane | E22: 3 | F22: Weapon | G22: 1d4 Piercing, Finesse, Light | I22: D&D Wiki | J22: =IF(D22="Mundane", 1, IF(D22="Common", 2, IF(D22="Uncommon", 3, IF(D22="Rare", 4, IF(D22="Very Rare", 5, IF(D22="Legendary", 6, 100)))))) -> 1
A23: Candle | B23: Six red wax candles. | C23: 0.01 | D23: Mundane | E23: n/a | F23: Adventuring Gear | G23: For 1 hour, a candle sheds bright light in a 5-foot radius and dim light for an additional 5 feet. | I23: PHB | J23: =IF(D23="Mundane", 1, IF(D23="Common", 2, IF(D23="Uncommon", 3, IF(D23="Rare", 4, IF(D23="Very Rare", 5, IF(D23="Legendary", 6, 100)))))) -> 1
A24: Carved Bone Statuette | B24: A carved ox bone female figure statue on a wooden base. The statue is 16" in height. | C24: 25 | D24: Mundane | E24: 1 | F24: Treasure | I24: DMG | J24: =IF(D24="Mundane", 1, IF(D24="Common", 2, IF(D24="Uncommon", 3, IF(D24="Rare", 4, IF(D24="Very Rare", 5, IF(D24="Legendary", 6, 100)))))) -> 1
A25: Chalk | B25: A small piece of chalk used to draw on any hard surface. | C25: 0.05 | D25: Mundane | E25: n/a | F25: Treasure | I25: Uberbeard | J25: =IF(D25="Mundane", 1, IF(D25="Common", 2, IF(D25="Uncommon", 3, IF(D25="Rare", 4, IF(D25="Very Rare", 5, IF(D25="Legendary", 6, 100)))))) -> 1
A26: Cloth Scrap | B26: An old scrap of cloth from a shirt or sheet of some kind. | C26: 0 | D26: Mundane | E26: n/a | F26: Treasure | I26: Uberbeard | J26: =IF(D26="Mundane", 1, IF(D26="Common", 2, IF(D26="Uncommon", 3, IF(D26="Rare", 4, IF(D26="Very Rare", 5, IF(D26="Legendary", 6, 100)))))) -> 1
A27: Cloth-of-gold Vestments | B27: These holy garments are made of silk interwoven with gold threads. | C27: 25 | D27: Mundane | E27: 3 | F27: Treasure | I27: DMG | J27: =IF(D27="Mundane", 1, IF(D27="Common", 2, IF(D27="Uncommon", 3, IF(D27="Rare", 4, IF(D27="Very Rare", 5, IF(D27="Legendary", 6, 100)))))) -> 1
A28: Comb | B28: A small wooden comb. | C28: 0.2 | D28: Mundane | E28: n/a | F28: Treasure | I28: Uberbeard | J28: =IF(D28="Mundane", 1, IF(D28="Common", 2, IF(D28="Uncommon", 3, IF(D28="Rare", 4, IF(D28="Very Rare", 5, IF(D28="Legendary", 6, 100)))))) -> 1
A29: Cooking Pot | B29: A cast iron cooking pot. It smells like it was last used for soup. | C29: 0.2 | D29: Mundane | E29: 2 | F29: Treasure | I29: Uberbeard | J29: =IF(D29="Mundane", 1, IF(D29="Common", 2, IF(D29="Uncommon", 3, IF(D29="Rare", 4, IF(D29="Very Rare", 5, IF(D29="Legendary", 6, 100)))))) -> 1
A30: Copper Acorns | B30: Heavy, solid copper acorns with perfect natural detail. | C30: 1 | D30: Mundane | E30: 2 | F30: Treasure | G30: These acorns drop from the oak-like trees that sprout on the graves of Copper Dragons. They can be lethal when falling, often embedding themselves in the ground. | I30: /u/gimme_some_sunshine | J30: =IF(D30="Mundane", 1, IF(D30="Common", 2, IF(D30="Uncommon", 3, IF(D30="Rare", 4, IF(D30="Very Rare", 5, IF(D30="Legendary", 6, 100)))))) -> 1
A31: Carved Beads | B31: A string of wooden carved beads, tied into a bracelet. | C31: 4 | D31: Mundane | E31: n/a | F31: Treasure | I31: Uberbeard | J31: 1
A32: Rusty Horseshoe | B32: An old rusty horseshoe, the metal may be worth something. | C32: 1 | D32: Mundane | E32: 0.5 | F32: Treasure | I32: Uberbeard | J32: 1
A33: Copper Ring | B33: A simple piece of jewlery. | C33: 2 | D33: Mundane | E33: n/a | F33: Treasure | I33: Uberbeard | J33: 1
A34: Copper Chalice | B34: A small copper chalice with a silver filigree. | C34: 25 | D34: Mundane | E34: 1 | F34: Treasure | I34: DMG | J34: =IF(D34="Mundane", 1, IF(D34="Common", 2, IF(D34="Uncommon", 3, IF(D34="Rare", 4, IF(D34="Very Rare", 5, IF(D34="Legendary", 6, 100)))))) -> 1
A35: Crowbar | B35: Using a crowbar grants advantage to Strength checks where the crowbar’s leverage can be applied. | C35: 2 | D35: Mundane | E35: 5 | F35: Adventuring Gear | I35: PHB | J35: =IF(D35="Mundane", 1, IF(D35="Common", 2, IF(D35="Uncommon", 3, IF(D35="Rare", 4, IF(D35="Very Rare", 5, IF(D35="Legendary", 6, 100)))))) -> 1
A36: Crude Box | B36: A wooden box. Carved by someone who has had no formal training in woodworking, and it shows. | C36: 0.15 | D36: Mundane | E36: 1 | F36: Treasure | I36: Uberbeard | J36: =IF(D36="Mundane", 1, IF(D36="Common", 2, IF(D36="Uncommon", 3, IF(D36="Rare", 4, IF(D36="Very Rare", 5, IF(D36="Legendary", 6, 100)))))) -> 1
A37: Crude Holy Symbol | B37: A crudely carved wooden holy symbol. | C37: 0.5 | D37: Mundane | E37: 1 | F37: Treasure | I37: Uberbeard | J37: =IF(D37="Mundane", 1, IF(D37="Common", 2, IF(D37="Uncommon", 3, IF(D37="Rare", 4, IF(D37="Very Rare", 5, IF(D37="Legendary", 6, 100)))))) -> 1
A38: Crude Pipe | B38: A crudely carved wooden pipe. | C38: 0.15 | D38: Mundane | E38: n/a | F38: Treasure | I38: Uberbeard | J38: =IF(D38="Mundane", 1, IF(D38="Common", 2, IF(D38="Uncommon", 3, IF(D38="Rare", 4, IF(D38="Very Rare", 5, IF(D38="Legendary", 6, 100)))))) -> 1
A39: Curious Powder Box | B39: Metal box of unidentifiable powder. | C39: 0.5 | D39: Mundane | E39: 2 | F39: Treasure | I39: Unknown | J39: =IF(D39="Mundane", 1, IF(D39="Common", 2, IF(D39="Uncommon", 3, IF(D39="Rare", 4, IF(D39="Very Rare", 5, IF(D39="Legendary", 6, 100)))))) -> 1
A40: Dead Fey | B40: A long-dead fey, dried and petrified as a trophy and hanging from ceiling. | C40: 5 | D40: Mundane | E40: 120 | F40: Treasure | I40: Unknown | J40: =IF(D40="Mundane", 1, IF(D40="Common", 2, IF(D40="Uncommon", 3, IF(D40="Rare", 4, IF(D40="Very Rare", 5, IF(D40="Legendary", 6, 100)))))) -> 1
...

Sheet Logic
B2: Rarity | C2: Item Count
B3: Mundane | C3: =COUNTIF('Dungeon Loot'!F2:Z1004, "=1") -> 186
B4: Common | C4: =COUNTIF('Dungeon Loot'!F2:Z1004, "=2") -> 274
B5: Uncommon | C5: =COUNTIF('Dungeon Loot'!F3:Z1005, "=3") -> 215
B6: Rare | C6: =COUNTIF('Dungeon Loot'!F4:Z1006, "=4") -> 192
B7: Very Rare | C7: =COUNTIF('Dungeon Loot'!F5:Z1007, "=5") -> 82
B8: Legendary | C8: =COUNTIF('Dungeon Loot'!F6:Z1008, "=6") -> 36

Sheet Form Submissions
A1: Timestamp | B1: Name | C1: Description | D1: Estimated Value | E1: Rarity | F1: Weight | G1: Category | H1: Properties | I1: Requirements | J1: Author
A2: 42696.96 | B2: Banshee Spirit Dagger | C2: Despite appearing to be a normal dagger, even those not able to recognise the presence of magic can tell that there is something imbued in the unassuming metal hilt and blade. When appraised it transpires that this blade was buried with a banshee and it's spirit has somehow been absorbed. Now whomever uses the dagger carries the risk that its spirit will be unleashed. | D2: 2000 | E2: Rare | F2: 2 lb. | G2: Weapon | H2: On a critical hit, it'll scream like her. It hasn't happened yet, but I imagine it'll either force the target to make a will save or be feared, or possibly drop to zero hit points. | J2: /u/Silanoch
A3: 42588.682 | B3: Eternity Armor | C3: Nigh-unbreakable golemsteel armor enchanted to withstand nearly any strike. If a ranged attack targets a friendly creature besides yourself within five feet radius, you can move them and take the shot to negate the damage and effects instead; if they are within a 10 feet radius, use your reaction. | E3: Legendary | F3: 80 | G3: Armor | H3: Heavy Armor| AC 20 | Str 20 | Stealth: Disadvantage | | J3: u/giratina2648
A4: 42588.643 | B4: Ring of Dubious Might | C4: A silver ring, encrusted with a small topaz. Upon wearing it on their finger, the wearer feels incredibly strong and confident. However, entering combat, their confidence immediately dissipates, leaving them terrified. | D4: 20gp | E4: Uncommon | F4: n/a | G4: Ring | J4: Jacos
A5: 42588.624 | B5: Cloak of the Shadow General | C5: A commanding cloak of authority, used to hide whole legions of armies against the Starwizards of the astral planes. | E5: Legendary | F5: 0 | G5: Wondrous Item | H5: 1/ Day: Creatures within a 30 feet radius, including the user, are granted the effects of greater invisibility, and cannot be detected by Truesight and other means of reveal, e.g. Mordenkainen's Faithful Hound. Charges are restored at dusk. | J5: u/giratina2648
A6: 42588.582 | B6: The Eye of Far Seeing (requires attunement) | C6: This legendary eyeball, said to have once been that of a gynosphinx, has the capability to scry at a radius of around 1000 miles. To use it, one must attune to it and to do so, one must gouge out one of their own eyes and replace it with the Eye of Far Seeing (similar to the eye of vecna). | D6: 30,000 gp | E6: Legendary | F6: 1-2 grams (sorry, I'm a metric guy) | G6: Wondrous Item | H6: Inserting this eye into one of your own eyes lots gives the ability to scry at will twice (or thrice) a day. If it is used more than that, your vision in that eye will start to fade and you will suffer exhaustion. | J6: J
A7: 42588.551 | B7: Animated Shield | C7: While holding this shield, you can speak its command word as a bonus action to cause it to animate. The shield leaps into the air and hovers in your space to protect you as if you were wielding it, leaving your hands free. The shield remains animated for 1 minute, until you use a bonus action to end this effect, or until you are incapacitated or die, at which point the shield falls to the ground or into your hand if you have one free. | E7: Very Rare | G7: Armor | H7: Requires Attunement | J7: DMG
A8: 42759.109 | B8: Stern Sword of Grammar Correction | C8: A dull, rather drab looking rapier inhabited with the intelligence of a hyper-particular grammarian. | E8: Very Rare | G8: Weapon | H8: Acts as a +1 sword vs any creature speaking with poor grammar construction. On a successful hit, the creature must save or begin using immaculate grammar (spelling gets a bump too), after which the sword attacks the creature as a mundane weapon. Shocks the wielder for 1 hp damage each time he or she uses poor grammar. | J8: Jeff C
A9: 42772.988 | B9: Boots of Feral Leaping | C9: Plain leather boots, tattered and worn, but glistening with a soft white light similar to the sunlight reflecting off freshly fallen snow. | D9: 1500 | E9: Rare | F9: 2 | G9: Armor | H9: When you wear these boots you can instill your leaps with incredible bursts of power. As a bonus action, you can attempt to leap. Make a DC16 Strength check: if you are successful, you can leap either 15 feet vertically or 20 feet horizontally. On a failure, you are knocked prone where you stand. | J9: /u/gimme_some_sunshine via Matt Mercer
A10: 42775.006 | B10: Ring Mail of Three Wishes | C10: This armor is Leather Armor with heavy rings sewn into it. The rings help reinforce the armor against blows from swords and axes. Three rings across the chest are made of brilliant gold that sheds dim light similar to daybreak. | D10: 1500 | E10: Rare | F10: 40 | G10: Armor | H10: When you are hit by a melee or ranged attack while wearing this armor, you can use your reaction to wish that you hadn't been hit. The attack deals no damage, but the armor class provided by the armor decreases by 1. After the third wish, the armor's rings vanish and it becomes nonmagical leather armor. | I10: Requires Attunement | J10: /u/gimme_some_sunshine
A11: 42775.008 | B11: Necromancer's Saddle | C11: Black leather saddle with streaks of red through the leather itself. A small amount of black smoke emanates from the saddle when it is holding still. | D11: 2000 | E11: Rare | F11: 30 | G11: Wondrous Item | H11: You can use an action to place this saddle on the corpse or skeleton of a Large creature and animate it as an undead mount. The undead creature's bones shift as necessary to create something similar to a warhorse skeleton (MM 273), which follows your mental commands as long as you are riding it. The effect lasts until you remove the saddle, or until the next dawn. When the effect ends, the undead creature crumbles into dust. | J11: /u/gimme_some_sunshine
A12: 42978.414 | B12: Sword of Bleeding | C12: A sharp one-sided blade that is slightly curved. | E12: Rare | G12: Weapon | H12: The creature must a Constitution saving throw of 14 or take an addition 1d6. The creature makes this check every turn until succeeded | J12: Brendan M
A13: 42978.414 | B13: Shield of Bashing | C13: A tough metal shield with a large stud in the center. | E13: Rare | G13: Weapon | H13: When running to a target from at least 20 feet. The target must make a Constitution saving throw of 14 or be knocked prone. Following attacks would then have advantage. | J13: Brendan M
A14: 42978.415 | B14: Crate of Chaos Mushrooms | C14: This wooden crate is about 60cm by 60cm by 40cm, with 'Chaos Mushrooms' burned into the lid in Sylvan. It fizzes with a faint magical aura, and smells delicious | D14: 2000 | E14: Rare | F14: 30lbs | G14: Treasure | H14: The box contains 1d10+4 'Chaos Mushrooms', which are considered a delecacy at Fey dinner parties. If a creature eats one of the Chaos Mushrooms, they must roll on the Wild Magic Surge table (PHB, p104) and are subject to the result. Each mushroom eaten requires a seperate roll. | J14: /u/Ragatan
A15: 43187.792 | B15: Spire of the Manticore | C15: You gain a +1 bonus to attack and damage rolls with this magical weapon, and it deals an additional 1d8 poison damage. The damage increases by 1d8 if the target is a Monstrosity or Beast. This weapon has 7 spikes hidden within the Barb at the end of the pike. As a ranged attack, you can launch a single spike at a target, each having a range of 100/200 ft. Each of these spikes deal 1d8 piercing damage. Every Morning at dawn, this weapon regrows all of it's spikes. | D15: 5,000gp | E15: Rare | F15: 18 | G15: Weapon | H15: Heavy, Reach, Two-Handed | I15: Requires Attunement | J15: Fin Fen
A16: 43187.795 | B16: Chimera's Mantel | C16: This Cloak is woven together from the fur of a lion and goat over the skin of a serpent. It bears the emblem of house Chimera. While wearing this cloak and attuned to it, you gain fire resistance. In addition you can use your action to exhale fire in a 15-foot cone. Each creature in that area must make a DC 15 Dexterity saving throw, taking 7d8 fire damage on a failed save, or half as much damage on a successful one. Once you use this ability, you cannot do so again until you take a short rest. | D16: 5,000gp | E16: Rare | F16: 1 | G16: Wondrous Item | I16: Requires Attunement | J16: Fin Fen
A17: 43187.8 | B17: Necklace of the Fang PAct | C17: This fiber necklace contains beads that separate several teeth from a variety of creatures. All together, it can support up to 7 teeth. While wearing this amulet, you can use an action to sap the remaining essence from a creature that has been brought to 0 hit points. Doing so turns the creature's flesh into ash and forges its life force into a tooth appropriate for its type which magically binds itself to the amulet. Each tooth has a type and a property. As a ritual, you can expend one tooth to gain its property for 24 hours or until a new ritual has been performed. Constructs, Oozes, and Plants are unaffected by this item. Undead whose essence you sap grant you a tooth with the type that it possessed in life rather than undeath. *Aberrations: You can magically transmit simple messages and images to any creature within 120 ft. that can understand a Language. This form of telepathy doesn't allow the receiving creature to telepathically respond. *Beasts: Your hit point maximum increases by an amount equal to twice your level. *Celestials: As an action, you can touch a target and remove any curse, disease, poison, blindness, or deafness condition. *Dragons: Your breath weapon gains a recharge of 6 and its damage die is increased to d8. *Elemental: You choose acid, cold, fire, lightning, poison, or thunder and gain resistance to that element. *Fey: Touching a creature, you magically know the creature's current emotional state. If the target fails a Charisma saving throw, you also know the creature's alignment. Celestials, Fiends, and Undead automatically fail the saving throw. *Fiends: You gain advantage on saving throws against Spells and other magical effects. *Giants: Your Strength score is 21. This property has no effect on you if your Strength is already 21 or higher without this necklace. *Humanoids: You become proficient in any two skills. Your proficiency bonus is doubled for any ability check you make that uses either of the chosen proficiencies. *Monstrosities: You gain Darkvision 60 Ft. and Tremorsense 60 Ft. In addition, you gain a keen sense of hearing and smelling which grants you advantage on Wisdom (Perception) checks that rely on hearing or smell. | D17: 25,000gp | E17: Very Rare | F17: 1 | G17: Wondrous Item | I17: Requires Attunement | J17: Fin Fen
